Workbook
Name SegmentaciónDeDatos_Ciudad1: #N/A
Name SegmentaciónDeDatos_Estrato1: #N/A
Name SegmentaciónDeDatos_Puede_Pagar_Solar1: #N/A
Name SegmentaciónDeDatos_Sector1: #N/A

Sheet Datos CSV
A1: ID_Cliente,Sector,Consumo_kWh_Mensual,Estrato,Ciudad,Area_m2,Factura_Mensual_COP,Puede_Pagar_Solar
A2: RES-0001,Residencial,209.8028491806739,4,Planeta Rica,77.2347139765763,130077.7664920179,No
A3: RES-0002,Residencial,108.1316144067627,1,SahagÃºn,122.8331686443322,67041.60093219286,No
A4: RES-0003,Residencial,196.7424775320083,4,Planeta Rica,100.2103056961305,121980.3360698451,No
A5: RES-0004,Residencial,145.1473119585891,2,Lorica,69.49660385643705,89991.33341432526,No
A6: RES-0005,Residencial,181.333309596719,3,Lorica,71.4441417279331,112426.6519499658,No
A7: RES-0006,Residencial,193.3247340938846,3,Lorica,64.64046996113845,119861.3351382084,No
A8: RES-0007,Residencial,147.337036528489,3,Planeta Rica,82.21845179419732,91348.9626476632,No
A9: RES-0008,Residencial,162.3960512184803,5,CeretÃ©,79.40322861280502,100685.5517554578,No
A10: RES-0009,Residencial,171.5868901585795,2,Lorica,79.3361319986691,106383.8718983193,No
A11: RES-0010,Residencial,118.7068683194641,3,SahagÃºn,76.76489227204958,73598.25835806776,No
A12: RES-0011,Residencial,166.2329727700826,3,CeretÃ©,87.78697826512247,103064.4431174512,No
... A461: IND-0061,Industrial,9814.0,5,MonterÃ­a,1328.385177040878,6084680.0,SÃ­

Sheet Limpieza de Datos
A1: CUARTILES | B1: Consumo_kWh_Mensual | C1: Area_m2 | D1: Factura_Mensual_COP
A2: Q1 | B2: =_xlfn.QUARTILE.EXC(Tabla1[Consumo_kWh_Mensual],1) -> 224.36044 | C2: =_xlfn.QUARTILE.EXC(Tabla1[Area_m2],1) -> 97.467702 | D2: =_xlfn.QUARTILE.EXC(Tabla1[Factura_Mensual_COP],1) -> 139103.47
A3: Q3 | B3: =_xlfn.QUARTILE.EXC(Tabla1[Consumo_kWh_Mensual],3) -> 4358.3059 | C3: =_xlfn.QUARTILE.EXC(Tabla1[Area_m2],3) -> 1079.5752 | D3: =_xlfn.QUARTILE.EXC(Tabla1[Factura_Mensual_COP],3) -> 2702149.7
A4: INT. Q | B4: =B3-B2 -> 4133.9455 | C4: =C3-C2 -> 982.10748 | D4: =D3-D2 -> 2563046.2
A5: LIMITE Q1 | B5: =B2-(1.5*B4) -> -5976.5577 | C5: =C2-(1.5*C4) -> -1375.6935 | D5: =D2-(1.5*D4) -> -3705465.8
A6: LIMITE Q3 | B6: =B3+(1.5*B4) -> 10559.224 | C6: =C3+(1.5*C4) -> 2552.7364 | D6: =D3+(1.5*D4) -> 6546718.9
I7: =COUNTIF(Tabla1[Estadistico Consumo_kWh_Mensual],NA()) -> 4 | J7: =COUNTIF(Tabla1[Estadistico Area_m2],NA()) -> 0 | K7: =COUNTIF(Tabla1[Estadistico Factura_Mensual_COP2],NA()) -> 4
A8: ID_Cliente | B8: Sector | C8: Consumo_kWh_Mensual | D8: Estrato | E8: Ciudad | F8: Area_m2 | G8: Factura_Mensual_COP | H8: Puede_Pagar_Solar | I8: Estadistico Consumo_kWh_Mensual | J8: Estadistico Area_m2 | K8: Estadistico Factura_Mensual_COP2
A9: RES-0001 | B9: Residencial | C9: 209.80285 | D9: 4 | E9: Planeta Rica | F9: 77.234714 | G9: 130077.77 | H9: No | I9: {=_xlfn.IFS(Tabla1[[#This Row],[Consumo_kWh_Mensual]]<$B$5,NA(),Tabla1[[#This Row],[Consumo_kWh_Mensual]]>$B$6,NA(),Tabla1[[#This Row],[Consumo_kWh_Mensual]]<$B$6,Tabla1[[#This Row],[Consumo_kWh_Mensual]])} -> 209.80285 | J9: {=_xlfn.IFS(Tabla1[[#This Row],[Area_m2]]<$C$5,NA(),Tabla1[[#This Row],[Area_m2]]>$C$6,NA(),Tabla1[[#This Row],[Area_m2]]<$C$6,Tabla1[[#This Row],[Area_m2]])} -> 77.234714 | K9: {=_xlfn.IFS(Tabla1[[#This Row],[Factura_Mensual_COP]]<$D$5,NA(),Tabla1[[#This Row],[Factura_Mensual_COP]]>$D$6,NA(),Tabla1[[#This Row],[Factura_Mensual_COP]]<$D$6,Tabla1[[#This Row],[Factura_Mensual_COP]])} -> 130077.77
A10: RES-0002 | B10: Residencial | C10: 108.13161 | D10: 1 | E10: Sahagún | F10: 122.83317 | G10: 67041.601 | H10: No | I10: {=_xlfn.IFS(Tabla1[[#This Row],[Consumo_kWh_Mensual]]<$B$5,NA(),Tabla1[[#This Row],[Consumo_kWh_Mensual]]>$B$6,NA(),Tabla1[[#This Row],[Consumo_kWh_Mensual]]<$B$6,Tabla1[[#This Row],[Consumo_kWh_Mensual]])} -> 108.13161 | J10: {=_xlfn.IFS(Tabla1[[#This Row],[Area_m2]]<$C$5,NA(),Tabla1[[#This Row],[Area_m2]]>$C$6,NA(),Tabla1[[#This Row],[Area_m2]]<$C$6,Tabla1[[#This Row],[Area_m2]])} -> 122.83317 | K10: {=_xlfn.IFS(Tabla1[[#This Row],[Factura_Mensual_COP]]<$D$5,NA(),Tabla1[[#This Row],[Factura_Mensual_COP]]>$D$6,NA(),Tabla1[[#This Row],[Factura_Mensual_COP]]<$D$6,Tabla1[[#This Row],[Factura_Mensual_COP]])} -> 67041.601
A11: RES-0003 | B11: Residencial | C11: 196.74248 | D11: 4 | E11: Planeta Rica | F11: 100.21031 | G11: 121980.34 | H11: No | I11: {=_xlfn.IFS(Tabla1[[#This Row],[Consumo_kWh_Mensual]]<$B$5,NA(),Tabla1[[#This Row],[Consumo_kWh_Mensual]]>$B$6,NA(),Tabla1[[#This Row],[Consumo_kWh_Mensual]]<$B$6,Tabla1[[#This Row],[Consumo_kWh_Mensual]])} -> 196.74248 | J11: {=_xlfn.IFS(Tabla1[[#This Row],[Area_m2]]<$C$5,NA(),Tabla1[[#This Row],[Area_m2]]>$C$6,NA(),Tabla1[[#This Row],[Area_m2]]<$C$6,Tabla1[[#This Row],[Area_m2]])} -> 100.21031 | K11: {=_xlfn.IFS(Tabla1[[#This Row],[Factura_Mensual_COP]]<$D$5,NA(),Tabla1[[#This Row],[Factura_Mensual_COP]]>$D$6,NA(),Tabla1[[#This Row],[Factura_Mensual_COP]]<$D$6,Tabla1[[#This Row],[Factura_Mensual_COP]])} -> 121980.34
A12: RES-0004 | B12: Residencial | C12: 145.14731 | D12: 2 | E12: Lorica | F12: 69.496604 | G12: 89991.333 | H12: No | I12: {=_xlfn.IFS(Tabla1[[#This Row],[Consumo_kWh_Mensual]]<$B$5,NA(),Tabla1[[#This Row],[Consumo_kWh_Mensual]]>$B$6,NA(),Tabla1[[#This Row],[Consumo_kWh_Mensual]]<$B$6,Tabla1[[#This Row],[Consumo_kWh_Mensual]])} -> 145.14731 | J12: {=_xlfn.IFS(Tabla1[[#This Row],[Area_m2]]<$C$5,NA(),Tabla1[[#This Row],[Area_m2]]>$C$6,NA(),Tabla1[[#This Row],[Area_m2]]<$C$6,Tabla1[[#This Row],[Area_m2]])} -> 69.496604 | K12: {=_xlfn.IFS(Tabla1[[#This Row],[Factura_Mensual_COP]]<$D$5,NA(),Tabla1[[#This Row],[Factura_Mensual_COP]]>$D$6,NA(),Tabla1[[#This Row],[Factura_Mensual_COP]]<$D$6,Tabla1[[#This Row],[Factura_Mensual_COP]])} -> 89991.333
A13: RES-0005 | B13: Residencial | C13: 181.33331 | D13: 3 | E13: Lorica | F13: 71.444142 | G13: 112426.65 | H13: No | I13: {=_xlfn.IFS(Tabla1[[#This Row],[Consumo_kWh_Mensual]]<$B$5,NA(),Tabla1[[#This Row],[Consumo_kWh_Mensual]]>$B$6,NA(),Tabla1[[#This Row],[Consumo_kWh_Mensual]]<$B$6,Tabla1[[#This Row],[Consumo_kWh_Mensual]])} -> 181.33331 | J13: {=_xlfn.IFS(Tabla1[[#This Row],[Area_m2]]<$C$5,NA(),Tabla1[[#This Row],[Area_m2]]>$C$6,NA(),Tabla1[[#This Row],[Area_m2]]<$C$6,Tabla1[[#This Row],[Area_m2]])} -> 71.444142 | K13: {=_xlfn.IFS(Tabla1[[#This Row],[Factura_Mensual_COP]]<$D$5,NA(),Tabla1[[#This Row],[Factura_Mensual_COP]]>$D$6,NA(),Tabla1[[#This Row],[Factura_Mensual_COP]]<$D$6,Tabla1[[#This Row],[Factura_Mensual_COP]])} -> 112426.65
A14: RES-0006 | B14: Residencial | C14: 193.32473 | D14: 3 | E14: Lorica | F14: 64.64047 | G14: 119861.34 | H14: No | I14: {=_xlfn.IFS(Tabla1[[#This Row],[Consumo_kWh_Mensual]]<$B$5,NA(),Tabla1[[#This Row],[Consumo_kWh_Mensual]]>$B$6,NA(),Tabla1[[#This Row],[Consumo_kWh_Mensual]]<$B$6,Tabla1[[#This Row],[Consumo_kWh_Mensual]])} -> 193.32473 | J14: {=_xlfn.IFS(Tabla1[[#This Row],[Area_m2]]<$C$5,NA(),Tabla1[[#This Row],[Area_m2]]>$C$6,NA(),Tabla1[[#This Row],[Area_m2]]<$C$6,Tabla1[[#This Row],[Area_m2]])} -> 64.64047 | K14: {=_xlfn.IFS(Tabla1[[#This Row],[Factura_Mensual_COP]]<$D$5,NA(),Tabla1[[#This Row],[Factura_Mensual_COP]]>$D$6,NA(),Tabla1[[#This Row],[Factura_Mensual_COP]]<$D$6,Tabla1[[#This Row],[Factura_Mensual_COP]])} -> 119861.34
A15: RES-0007 | B15: Residencial | C15: 147.33704 | D15: 3 | E15: Planeta Rica | F15: 82.218452 | G15: 91348.963 | H15: No | I15: {=_xlfn.IFS(Tabla1[[#This Row],[Consumo_kWh_Mensual]]<$B$5,NA(),Tabla1[[#This Row],[Consumo_kWh_Mensual]]>$B$6,NA(),Tabla1[[#This Row],[Consumo_kWh_Mensual]]<$B$6,Tabla1[[#This Row],[Consumo_kWh_Mensual]])} -> 147.33704 | J15: {=_xlfn.IFS(Tabla1[[#This Row],[Area_m2]]<$C$5,NA(),Tabla1[[#This Row],[Area_m2]]>$C$6,NA(),Tabla1[[#This Row],[Area_m2]]<$C$6,Tabla1[[#This Row],[Area_m2]])} -> 82.218452 | K15: {=_xlfn.IFS(Tabla1[[#This Row],[Factura_Mensual_COP]]<$D$5,NA(),Tabla1[[#This Row],[Factura_Mensual_COP]]>$D$6,NA(),Tabla1[[#This Row],[Factura_Mensual_COP]]<$D$6,Tabla1[[#This Row],[Factura_Mensual_COP]])} -> 91348.963
A16: RES-0008 | B16: Residencial | C16: 162.39605 | D16: 5 | E16: Cereté | F16: 79.403229 | G16: 100685.55 | H16: No | I16: {=_xlfn.IFS(Tabla1[[#This Row],[Consumo_kWh_Mensual]]<$B$5,NA(),Tabla1[[#This Row],[Consumo_kWh_Mensual]]>$B$6,NA(),Tabla1[[#This Row],[Consumo_kWh_Mensual]]<$B$6,Tabla1[[#This Row],[Consumo_kWh_Mensual]])} -> 162.39605 | J16: {=_xlfn.IFS(Tabla1[[#This Row],[Area_m2]]<$C$5,NA(),Tabla1[[#This Row],[Area_m2]]>$C$6,NA(),Tabla1[[#This Row],[Area_m2]]<$C$6,Tabla1[[#This Row],[Area_m2]])} -> 79.403229 | K16: {=_xlfn.IFS(Tabla1[[#This Row],[Factura_Mensual_COP]]<$D$5,NA(),Tabla1[[#This Row],[Factura_Mensual_COP]]>$D$6,NA(),Tabla1[[#This Row],[Factura_Mensual_COP]]<$D$6,Tabla1[[#This Row],[Factura_Mensual_COP]])} -> 100685.55
A17: RES-0009 | B17: Residencial | C17: 171.58689 | D17: 2 | E17: Lorica | F17: 79.336132 | G17: 106383.87 | H17: No | I17: {=_xlfn.IFS(Tabla1[[#This Row],[Consumo_kWh_Mensual]]<$B$5,NA(),Tabla1[[#This Row],[Consumo_kWh_Mensual]]>$B$6,NA(),Tabla1[[#This Row],[Consumo_kWh_Mensual]]<$B$6,Tabla1[[#This Row],[Consumo_kWh_Mensual]])} -> 171.58689 | J17: {=_xlfn.IFS(Tabla1[[#This Row],[Area_m2]]<$C$5,NA(),Tabla1[[#This Row],[Area_m2]]>$C$6,NA(),Tabla1[[#This Row],[Area_m2]]<$C$6,Tabla1[[#This Row],[Area_m2]])} -> 79.336132 | K17: {=_xlfn.IFS(Tabla1[[#This Row],[Factura_Mensual_COP]]<$D$5,NA(),Tabla1[[#This Row],[Factura_Mensual_COP]]>$D$6,NA(),Tabla1[[#This Row],[Factura_Mensual_COP]]<$D$6,Tabla1[[#This Row],[Factura_Mensual_COP]])} -> 106383.87
A18: RES-0010 | B18: Residencial | C18: 118.70687 | D18: 3 | E18: Sahagún | F18: 76.764892 | G18: 73598.258 | H18: No | I18: {=_xlfn.IFS(Tabla1[[#This Row],[Consumo_kWh_Mensual]]<$B$5,NA(),Tabla1[[#This Row],[Consumo_kWh_Mensual]]>$B$6,NA(),Tabla1[[#This Row],[Consumo_kWh_Mensual]]<$B$6,Tabla1[[#This Row],[Consumo_kWh_Mensual]])} -> 118.70687 | J18: {=_xlfn.IFS(Tabla1[[#This Row],[Area_m2]]<$C$5,NA(),Tabla1[[#This Row],[Area_m2]]>$C$6,NA(),Tabla1[[#This Row],[Area_m2]]<$C$6,Tabla1[[#This Row],[Area_m2]])} -> 76.764892 | K18: {=_xlfn.IFS(Tabla1[[#This Row],[Factura_Mensual_COP]]<$D$5,NA(),Tabla1[[#This Row],[Factura_Mensual_COP]]>$D$6,NA(),Tabla1[[#This Row],[Factura_Mensual_COP]]<$D$6,Tabla1[[#This Row],[Factura_Mensual_COP]])} -> 73598.258
A19: RES-0011 | B19: Residencial | C19: 166.23297 | D19: 3 | E19: Cereté | F19: 87.786978 | G19: 103064.44 | H19: No | I19: {=_xlfn.IFS(Tabla1[[#This Row],[Consumo_kWh_Mensual]]<$B$5,NA(),Tabla1[[#This Row],[Consumo_kWh_Mensual]]>$B$6,NA(),Tabla1[[#This Row],[Consumo_kWh_Mensual]]<$B$6,Tabla1[[#This Row],[Consumo_kWh_Mensual]])} -> 166.23297 | J19: {=_xlfn.IFS(Tabla1[[#This Row],[Area_m2]]<$C$5,NA(),Tabla1[[#This Row],[Area_m2]]>$C$6,NA(),Tabla1[[#This Row],[Area_m2]]<$C$6,Tabla1[[#This Row],[Area_m2]])} -> 87.786978 | K19: {=_xlfn.IFS(Tabla1[[#This Row],[Factura_Mensual_COP]]<$D$5,NA(),Tabla1[[#This Row],[Factura_Mensual_COP]]>$D$6,NA(),Tabla1[[#This Row],[Factura_Mensual_COP]]<$D$6,Tabla1[[#This Row],[Factura_Mensual_COP]])} -> 103064.44
A20: RES-0012 | B20: Residencial | C20: 97.323642 | D20: 3 | E20: Planeta Rica | F20: 72.937667 | G20: 60340.658 | H20: No | I20: {=_xlfn.IFS(Tabla1[[#This Row],[Consumo_kWh_Mensual]]<$B$5,NA(),Tabla1[[#This Row],[Consumo_kWh_Mensual]]>$B$6,NA(),Tabla1[[#This Row],[Consumo_kWh_Mensual]]<$B$6,Tabla1[[#This Row],[Consumo_kWh_Mensual]])} -> 97.323642 | J20: {=_xlfn.IFS(Tabla1[[#This Row],[Area_m2]]<$C$5,NA(),Tabla1[[#This Row],[Area_m2]]>$C$6,NA(),Tabla1[[#This Row],[Area_m2]]<$C$6,Tabla1[[#This Row],[Area_m2]])} -> 72.937667 | K20: {=_xlfn.IFS(Tabla1[[#This Row],[Factura_Mensual_COP]]<$D$5,NA(),Tabla1[[#This Row],[Factura_Mensual_COP]]>$D$6,NA(),Tabla1[[#This Row],[Factura_Mensual_COP]]<$D$6,Tabla1[[#This Row],[Factura_Mensual_COP]])} -> 60340.658
... A468: IND-0061 | B468: Industrial | C468: 9814 | D468: 5 | E468: Montería | F468: 1328.3852 | G468: 6084680 | H468: Sí | I468: {=_xlfn.IFS(Tabla1[[#This Row],[Consumo_kWh_Mensual]]<$B$5,NA(),Tabla1[[#This Row],[Consumo_kWh_Mensual]]>$B$6,NA(),Tabla1[[#This Row],[Consumo_kWh_Mensual]]<$B$6,Tabla1[[#This Row],[Consumo_kWh_Mensual]])} -> 9814 | J468: {=_xlfn.IFS(Tabla1[[#This Row],[Area_m2]]<$C$5,NA(),Tabla1[[#This Row],[Area_m2]]>$C$6,NA(),Tabla1[[#This Row],[Area_m2]]<$C$6,Tabla1[[#This Row],[Area_m2]])} -> 1328.3852 | K468: {=_xlfn.IFS(Tabla1[[#This Row],[Factura_Mensual_COP]]<$D$5,NA(),Tabla1[[#This Row],[Factura_Mensual_COP]]>$D$6,NA(),Tabla1[[#This Row],[Factura_Mensual_COP]]<$D$6,Tabla1[[#This Row],[Factura_Mensual_COP]])} -> 6084680

Sheet Presentación Excel

Sheet Datos Limpios
A1: ID_Cliente | B1: Sector | C1: Consumo_kWh_Mensual | D1: Estrato | E1: Ciudad | F1: Area_m2 | G1: Factura_Mensual_COP | H1: Puede_Pagar_Solar | I1: Validar
A2: RES-0001 | B2: Residencial | C2: 209.80285 | D2: 4 | E2: Planeta Rica | F2: 77.234714 | G2: 130077.77 | H2: No | I2: =IF(COUNTIF(DATOS_LIMPIOS_ELECT[[#This Row],[ID_Cliente]:[Puede_Pagar_Solar]],NA()),"NO VALIDO","VALIDO") -> VALIDO
A3: RES-0002 | B3: Residencial | C3: 108.13161 | D3: 1 | E3: Sahagún | F3: 122.83317 | G3: 67041.601 | H3: No | I3: =IF(COUNTIF(DATOS_LIMPIOS_ELECT[[#This Row],[ID_Cliente]:[Puede_Pagar_Solar]],NA()),"NO VALIDO","VALIDO") -> VALIDO
A4: RES-0003 | B4: Residencial | C4: 196.74248 | D4: 4 | E4: Planeta Rica | F4: 100.21031 | G4: 121980.34 | H4: No | I4: =IF(COUNTIF(DATOS_LIMPIOS_ELECT[[#This Row],[ID_Cliente]:[Puede_Pagar_Solar]],NA()),"NO VALIDO","VALIDO") -> VALIDO
A5: RES-0004 | B5: Residencial | C5: 145.14731 | D5: 2 | E5: Lorica | F5: 69.496604 | G5: 89991.333 | H5: No | I5: =IF(COUNTIF(DATOS_LIMPIOS_ELECT[[#This Row],[ID_Cliente]:[Puede_Pagar_Solar]],NA()),"NO VALIDO","VALIDO") -> VALIDO
A6: RES-0005 | B6: Residencial | C6: 181.33331 | D6: 3 | E6: Lorica | F6: 71.444142 | G6: 112426.65 | H6: No | I6: =IF(COUNTIF(DATOS_LIMPIOS_ELECT[[#This Row],[ID_Cliente]:[Puede_Pagar_Solar]],NA()),"NO VALIDO","VALIDO") -> VALIDO
A7: RES-0006 | B7: Residencial | C7: 193.32473 | D7: 3 | E7: Lorica | F7: 64.64047 | G7: 119861.34 | H7: No | I7: =IF(COUNTIF(DATOS_LIMPIOS_ELECT[[#This Row],[ID_Cliente]:[Puede_Pagar_Solar]],NA()),"NO VALIDO","VALIDO") -> VALIDO
A8: RES-0007 | B8: Residencial | C8: 147.33704 | D8: 3 | E8: Planeta Rica | F8: 82.218452 | G8: 91348.963 | H8: No | I8: =IF(COUNTIF(DATOS_LIMPIOS_ELECT[[#This Row],[ID_Cliente]:[Puede_Pagar_Solar]],NA()),"NO VALIDO","VALIDO") -> VALIDO
A9: RES-0008 | B9: Residencial | C9: 162.39605 | D9: 5 | E9: Cereté | F9: 79.403229 | G9: 100685.55 | H9: No | I9: =IF(COUNTIF(DATOS_LIMPIOS_ELECT[[#This Row],[ID_Cliente]:[Puede_Pagar_Solar]],NA()),"NO VALIDO","VALIDO") -> VALIDO
A10: RES-0009 | B10: Residencial | C10: 171.58689 | D10: 2 | E10: Lorica | F10: 79.336132 | G10: 106383.87 | H10: No | I10: =IF(COUNTIF(DATOS_LIMPIOS_ELECT[[#This Row],[ID_Cliente]:[Puede_Pagar_Solar]],NA()),"NO VALIDO","VALIDO") -> VALIDO
A11: RES-0010 | B11: Residencial | C11: 118.70687 | D11: 3 | E11: Sahagún | F11: 76.764892 | G11: 73598.258 | H11: No | I11: =IF(COUNTIF(DATOS_LIMPIOS_ELECT[[#This Row],[ID_Cliente]:[Puede_Pagar_Solar]],NA()),"NO VALIDO","VALIDO") -> VALIDO
A12: RES-0011 | B12: Residencial | C12: 166.23297 | D12: 3 | E12: Cereté | F12: 87.786978 | G12: 103064.44 | H12: No | I12: =IF(COUNTIF(DATOS_LIMPIOS_ELECT[[#This Row],[ID_Cliente]:[Puede_Pagar_Solar]],NA()),"NO VALIDO","VALIDO") -> VALIDO
A13: RES-0012 | B13: Residencial | C13: 97.323642 | D13: 3 | E13: Planeta Rica | F13: 72.937667 | G13: 60340.658 | H13: No | I13: =IF(COUNTIF(DATOS_LIMPIOS_ELECT[[#This Row],[ID_Cliente]:[Puede_Pagar_Solar]],NA()),"NO VALIDO","VALIDO") -> VALIDO
... A451: IND-0150 | B451: Industrial | C451: 7791.9734 | D451: 5 | E451: Cereté | F451: 1671.6537 | G451: 4831023.5 | H451: Sí | I451: =IF(COUNTIF(DATOS_LIMPIOS_ELECT[[#This Row],[ID_Cliente]:[Puede_Pagar_Solar]],NA()),"NO VALIDO","VALIDO") -> VALIDO
A452: IND-0108 | B452: Industrial | C452: #N/A | D452: 5 | E452: Cereté | F452: 1103.992 | G452: #N/A | H452: Sí | I452: =IF(COUNTIF(DATOS_LIMPIOS_ELECT[[#This Row],[ID_Cliente]:[Puede_Pagar_Solar]],NA()),"NO VALIDO","VALIDO") -> NO VALIDO
A453: IND-0145 | B453: Industrial | C453: #N/A | D453: 6 | E453: Sahagún | F453: 1396.0083 | G453: #N/A | H453: Sí | I453: =IF(COUNTIF(DATOS_LIMPIOS_ELECT[[#This Row],[ID_Cliente]:[Puede_Pagar_Solar]],NA()),"NO VALIDO","VALIDO") -> NO VALIDO
A454: RES-0118 | B454: Residencial | C454: 891.25509 | D454: 2 | E454: Sahagún | F454: 93.593193 | G454: 552578.16 | H454: No | I454: =IF(COUNTIF(DATOS_LIMPIOS_ELECT[[#This Row],[ID_Cliente]:[Puede_Pagar_Solar]],NA()),"NO VALIDO","VALIDO") -> VALIDO
A455: RES-0031 | B455: Residencial | C455: 2190.6292 | D455: 4 | E455: Montería | F455: 50.729701 | G455: 1358190.1 | H455: No | I455: =IF(COUNTIF(DATOS_LIMPIOS_ELECT[[#This Row],[ID_Cliente]:[Puede_Pagar_Solar]],NA()),"NO VALIDO","VALIDO") -> VALIDO
A456: IND-0116 | B456: Industrial | C456: #N/A | D456: 6 | E456: Cereté | F456: 1022.3869 | G456: #N/A | H456: Sí | I456: =IF(COUNTIF(DATOS_LIMPIOS_ELECT[[#This Row],[ID_Cliente]:[Puede_Pagar_Solar]],NA()),"NO VALIDO","VALIDO") -> NO VALIDO
A457: IND-0008 | B457: Industrial | C457: 5795 | D457: 5 | E457: Montería | F457: 1591.8383 | G457: 3592900 | H457: Sí | I457: =IF(COUNTIF(DATOS_LIMPIOS_ELECT[[#This Row],[ID_Cliente]:[Puede_Pagar_Solar]],NA()),"NO VALIDO","VALIDO") -> VALIDO
A458: COM-0068 | B458: Comercial | C458: 6631.4365 | D458: 5 | E458: Lorica | F458: 266.54856 | G458: 4111490.6 | H458: Sí | I458: =IF(COUNTIF(DATOS_LIMPIOS_ELECT[[#This Row],[ID_Cliente]:[Puede_Pagar_Solar]],NA()),"NO VALIDO","VALIDO") -> VALIDO
A459: RES-0051 | B459: Residencial | C459: 931 | D459: 2 | E459: Lorica | F459: 84.645074 | G459: 577220 | H459: No | I459: =IF(COUNTIF(DATOS_LIMPIOS_ELECT[[#This Row],[ID_Cliente]:[Puede_Pagar_Solar]],NA()),"NO VALIDO","VALIDO") -> VALIDO
A460: RES-0085 | B460: Residencial | C460: #N/A | D460: 5 | E460: Lorica | F460: 72.293728 | G460: #N/A | H460: No | I460: =IF(COUNTIF(DATOS_LIMPIOS_ELECT[[#This Row],[ID_Cliente]:[Puede_Pagar_Solar]],NA()),"NO VALIDO","VALIDO") -> NO VALIDO
A461: IND-0061 | B461: Industrial | C461: 9814 | D461: 5 | E461: Montería | F461: 1328.3852 | G461: 6084680 | H461: Sí | I461: =IF(COUNTIF(DATOS_LIMPIOS_ELECT[[#This Row],[ID_Cliente]:[Puede_Pagar_Solar]],NA()),"NO VALIDO","VALIDO") -> VALIDO

Sheet Estadistica Descriptiva
A1: Analisis
A2: Valores | B2: Consumo_kWh_Mensual | C2: Area_m2 | D2: Factura_Mensual_COP
A3: Minimo | B3: =_xlfn.MINIFS(DATOS_LIMPIOS_ELECT[Consumo_kWh_Mensual],DATOS_LIMPIOS_ELECT[Validar],"VALIDO") -> 51.248594 | C3: =_xlfn.MINIFS(DATOS_LIMPIOS_ELECT[Area_m2],DATOS_LIMPIOS_ELECT[Validar],"VALIDO") -> 39.553701 | D3: =_xlfn.MINIFS(DATOS_LIMPIOS_ELECT[Factura_Mensual_COP],DATOS_LIMPIOS_ELECT[Validar],"VALIDO") -> 31774.129
A4: Maximo | B4: =_xlfn.MAXIFS(DATOS_LIMPIOS_ELECT[Consumo_kWh_Mensual],DATOS_LIMPIOS_ELECT[Validar],"VALIDO") -> 9814 | C4: =_xlfn.MAXIFS(DATOS_LIMPIOS_ELECT[Area_m2],DATOS_LIMPIOS_ELECT[Validar],"VALIDO") -> 1850.4208 | D4: =_xlfn.MAXIFS(DATOS_LIMPIOS_ELECT[Factura_Mensual_COP],DATOS_LIMPIOS_ELECT[Validar],"VALIDO") -> 6084680
A5: Promedio | B5: =AVERAGEIFS(DATOS_LIMPIOS_ELECT[Consumo_kWh_Mensual],DATOS_LIMPIOS_ELECT[Validar],"VALIDO") -> 2135.0943 | C5: =AVERAGEIFS(DATOS_LIMPIOS_ELECT[Area_m2],DATOS_LIMPIOS_ELECT[Validar],"VALIDO") -> 543.42632 | D5: =AVERAGEIFS(DATOS_LIMPIOS_ELECT[Factura_Mensual_COP],DATOS_LIMPIOS_ELECT[Validar],"VALIDO") -> 1323758.4
A7: Conteo
A8: Sector | B8: Cantidad
A9: Residencial | B9: =COUNTIFS(DATOS_LIMPIOS_ELECT[Sector],'Estadistica Descriptiva'!A9,DATOS_LIMPIOS_ELECT[Validar],"VALIDO") -> 153
A10: Comercial | B10: =COUNTIFS(DATOS_LIMPIOS_ELECT[Sector],'Estadistica Descriptiva'!A10,DATOS_LIMPIOS_ELECT[Validar],"VALIDO") -> 151
A11: Industrial | B11: =COUNTIFS(DATOS_LIMPIOS_ELECT[Sector],'Estadistica Descriptiva'!A11,DATOS_LIMPIOS_ELECT[Validar],"VALIDO") -> 152
A13: Ciudad | B13: Cantidad
A14: Planeta Rica | B14: =COUNTIFS(DATOS_LIMPIOS_ELECT[Ciudad],'Estadistica Descriptiva'!A14,DATOS_LIMPIOS_ELECT[Validar],"VALIDO") -> 88
A15: Sahagún | B15: =COUNTIFS(DATOS_LIMPIOS_ELECT[Ciudad],'Estadistica Descriptiva'!A15,DATOS_LIMPIOS_ELECT[Validar],"VALIDO") -> 95
A16: Lorica | B16: =COUNTIFS(DATOS_LIMPIOS_ELECT[Ciudad],'Estadistica Descriptiva'!A16,DATOS_LIMPIOS_ELECT[Validar],"VALIDO") -> 79
A17: Cereté | B17: =COUNTIFS(DATOS_LIMPIOS_ELECT[Ciudad],'Estadistica Descriptiva'!A17,DATOS_LIMPIOS_ELECT[Validar],"VALIDO") -> 100
A18: Montería | B18: =COUNTIFS(DATOS_LIMPIOS_ELECT[Ciudad],'Estadistica Descriptiva'!A18,DATOS_LIMPIOS_ELECT[Validar],"VALIDO") -> 94
A20: Puede_Pagar_Solar | B20: Cantidad
A21: Sí | B21: =COUNTIFS(DATOS_LIMPIOS_ELECT[Puede_Pagar_Solar],'Estadistica Descriptiva'!A21,DATOS_LIMPIOS_ELECT[Validar],"VALIDO") -> 316
A22: No | B22: =COUNTIFS(DATOS_LIMPIOS_ELECT[Puede_Pagar_Solar],'Estadistica Descriptiva'!A22,DATOS_LIMPIOS_ELECT[Validar],"VALIDO") -> 140
A24: Estrato | B24: Cantidad
A25: 1 | B25: =COUNTIFS(DATOS_LIMPIOS_ELECT[Estrato],'Estadistica Descriptiva'!A25,DATOS_LIMPIOS_ELECT[Validar],"VALIDO") -> 16
A26: 2 | B26: =COUNTIFS(DATOS_LIMPIOS_ELECT[Estrato],'Estadistica Descriptiva'!A26,DATOS_LIMPIOS_ELECT[Validar],"VALIDO") -> 37
A27: 3 | B27: =COUNTIFS(DATOS_LIMPIOS_ELECT[Estrato],'Estadistica Descriptiva'!A27,DATOS_LIMPIOS_ELECT[Validar],"VALIDO") -> 77
A28: 4 | B28: =COUNTIFS(DATOS_LIMPIOS_ELECT[Estrato],'Estadistica Descriptiva'!A28,DATOS_LIMPIOS_ELECT[Validar],"VALIDO") -> 122
A29: 5 | B29: =COUNTIFS(DATOS_LIMPIOS_ELECT[Estrato],'Estadistica Descriptiva'!A29,DATOS_LIMPIOS_ELECT[Validar],"VALIDO") -> 138
A30: 6 | B30: =COUNTIFS(DATOS_LIMPIOS_ELECT[Estrato],'Estadistica Descriptiva'!A30,DATOS_LIMPIOS_ELECT[Validar],"VALIDO") -> 66

Sheet Reporte 1
A1: Validar | B1: VALIDO
A3: Etiquetas de fila | B3: Suma de Factura_Mensual_COP | C3: Suma de Consumo_kWh_Mensual
A4: No | B4: 17004930 | C4: 27427.307
A5: Sí
A6: Cereté
A7: Comercial
A8: 3 | B8: 1353809.6 | C8: 2183.5639
A9: 4 | B9: 7738739.3 | C9: 12481.838
A10: 5 | B10: 7209392.3 | C10: 11628.052
A11: 6 | B11: 2086581.9 | C11: 3365.4547
A12: Industrial
A13: 4 | B13: 16040473 | C13: 25871.731
A14: 5 | B14: 60528922 | C14: 97627.293
A15: 6 | B15: 38912376 | C15: 62761.897
A16: Residencial
A17: 4 | B17: 171972.64 | C17: 277.37523
A18: Lorica
A19: Comercial
A20: 3 | B20: 1465900.6 | C20: 2364.3558
A21: 4 | B21: 4603024.5 | C21: 7424.2331
A22: 5 | B22: 8529754.6 | C22: 13757.669
A23: 6 | B23: 1315733 | C23: 2122.15
A24: Industrial
A25: 4 | B25: 8591318.5 | C25: 13856.965
A26: 5 | B26: 71838365 | C26: 115868.33
A27: 6 | B27: 32482704 | C27: 52391.459
A28: Residencial
A29: 5 | B29: 198675.76 | C29: 320.44478
A30: Montería
A31: Comercial
A32: 3 | B32: 4789704.7 | C32: 7725.3302
A33: 4 | B33: 4686022.4 | C33: 7558.1007
A34: 5 | B34: 5202358.6 | C34: 8390.901
A35: 6 | B35: 1399737.4 | C35: 2257.6409
A36: Industrial
A37: 4 | B37: 21155140 | C37: 34121.193
A38: 5 | B38: 34738056 | C38: 56029.123
A39: 6 | B39: 29719954 | C39: 47935.409
A40: Residencial
A41: 3 | B41: 512110.6 | C41: 825.98484
...

Sheet Reporte 2
A2: Validar | B2: VALIDO
A4: Reporte 2 | B4: Factura_Mensual_COP
A5: No
A6: 1
A7: Residencial
A8: Cereté | B8: 448341.02
A9: Lorica | B9: 139070.96
A10: Montería | B10: 411589.63
A11: Planeta Rica | B11: 272106.28
A12: Sahagún | B12: 600489.45

Sheet Presentación Power Bi

Sheet Informe Power Bi
